Workbook

Sheet Overview
A1: GLOBAL VTS | INVENTORY v0.3
A3: Version 0.3 | 29 September 2026 | Supersedes both v0.1 workbooks. Research counts, not a verified worldwide census.
A6: TSS SOURCE ENTRIES | E6: VTS SERVICE RECORDS | I6: REPORTING SCHEME RECORDS
A7: =COUNTA('TSS Candidates'!A7:A176) | E7: =COUNTA('VTS Services'!A7:A63) | I7: =COUNTA('Reporting Schemes'!A7:A33)
A11: DO NOT USE 170 AS THE WORLDWIDE TSS OR VTS TOTAL. The official baseline and later amendments remain unreconciled. Component, area and publication counts are still undetermined.
A15: RESEARCH PROGRESS | I15: COUNTING CHECKS
A16: Identification screening started | G16: =COUNTA('TSS Candidates'!A7:A176)-COUNTIF('TSS Candidates'!R7:R176,"Candidate recorded") | I16: Mandatory schemes | L16: =COUNTIF('Reporting Schemes'!D7:D33,"Mandatory for applicable vessels")
A17: Initial named associations evidenced | G17: =COUNTIF('TSS Candidates'!R7:R176,"Initial association evidenced") | I17: Voluntary schemes | L17: =COUNTIF('Reporting Schemes'!D7:D33,"Voluntary")
A18: Source records not yet screened | G18: =COUNTIF('TSS Candidates'!R7:R176,"Candidate recorded") | I18: Non-additive TSS children | L18: =COUNTA('TSS Components'!A7:A107)
A19: Fully audited operational records | G19: =COUNTIF('TSS Candidates'!R7:R176,"Fully audited")
A20: Five-record research batches | G20: =COUNTA('Batches'!A7:A40) | I20: NOT YET DETERMINED Worldwide TSS total Distinct VTS areas Guide entries and pages
A21: Open research issues | G21: =COUNTIF('Issues'!E7:E34,"Open")
A22: Sources and source leads | G22: =COUNTA('Sources'!A7:A142)
A25: AUDIT OUTCOME AND LIMITS
A27: v0.3 adds first-pass Stage 4 research for B10 to B34 (125 source rows): TSS identity, VTS and mandatory reporting findings, with primary sources.
A29: Merge audit downgraded one VTS finding and three 'Confirmed absent' findings, and reclassified VTS and port reporting duties under their services. See Stage 4 Findings and research/stage4/merge_log.md.
A31: Services and schemes marked Lead only are research leads and are excluded from counted totals. Unresolved never means absent.
A33: B01 to B09 remain at v0.2 screening level. The official baseline (Ships' Routeing 2025, UKHO Notice 17) is still unreconciled.
A35: Use Audit Findings for corrections, ID Crosswalk for old identifiers, and Legacy Links for the earlier relationship assertions.
A37: RESEARCH ONLY. No operational channels, reporting lines, coordinates or passage instructions are authorised by this workbook.
A40: STAGE 4 FIRST PASS: B10 TO B34
A41: Records researched | G41: =COUNTA('Stage 4 Findings'!A7:A131)
A42: TSS identity confirmed | G42: =COUNTIF('Stage 4 Findings'!G7:G131,"Confirmed")
A43: VTS: confirmed present | G43: =COUNTIF('Stage 4 Findings'!K7:K131,"Confirmed present")
A44: VTS: unresolved | G44: =COUNTIF('Stage 4 Findings'!K7:K131,"Unresolved")
A45: VTS: confirmed absent | G45: =COUNTIF('Stage 4 Findings'!K7:K131,"Confirmed absent")
A46: Mandatory reporting: confirmed present | G46: =COUNTIF('Stage 4 Findings'!N7:N131,"Confirmed present")
A47: Mandatory reporting: unresolved | G47: =COUNTIF('Stage 4 Findings'!N7:N131,"Unresolved")
A48: Mandatory reporting: confirmed absent | G48: =COUNTIF('Stage 4 Findings'!N7:N131,"Confirmed absent")
A49: Withdrawn or superseded | G49: =COUNTIF('Stage 4 Findings'!I7:I131,"Withdrawn/superseded")
A50: Counted VTS services in register (excludes leads) | G50: =COUNTA('VTS Services'!A7:A63)-COUNTIF('VTS Services'!F7:F63,"Stage 4 research lead (not counted)")

Sheet TSS Candidates
A1: TSS CANDIDATE INVENTORY
A3: Version 0.3 | 29 September 2026 | TSS Candidates. Reconciled register; see Audit Findings and Overview for limits.
A6: Record ID | B6: Region | C6: Candidate source label | D6: Record type | E6: Baseline status | F6: VTS screening | G6: Reporting screening | H6: Related service IDs | I6: Related reporting IDs | J6: Grouping / reconciliation note | K6: Source ID | L6: Source URL | M6: Source locator | N6: Source limitation | O6: Additional evidence IDs | P6: Additional evidence URLs | Q6: Batch | R6: Review stage | S6: Last record check
A7: TSS-0001 | B7: British Isles and southern North Sea | C7: In the approaches to the River Humber | D7: Source entry; component check pending | E7: Provisional: official baseline reconciliation pending | F7: Not researched | G7: Not researched | K7: SRC-001 | L7: https://www.scribd.com/document/1014775753/1-1-IMO-Adopted-Traffic-Separation-Schemes-on-the-ADMIRALTY-Chart-Series | M7: Notice 17; scheme label: In the approaches to the River Humber | N7: UKHO-labelled document on third-party host; edition and currency unverified. | Q7: B01 | R7: Candidate recorded | S7: Not established
A8: TSS-0002 | B8: British Isles and southern North Sea | C8: In the Sunk area and northern Approaches to the Thames Estuary | D8: Source entry; component check pending | E8: Provisional: official baseline reconciliation pending | F8: Not researched | G8: Not researched | K8: SRC-001 | L8: https://www.scribd.com/document/1014775753/1-1-IMO-Adopted-Traffic-Separation-Schemes-on-the-ADMIRALTY-Chart-Series | M8: Notice 17; scheme label: In the Sunk area and northern Approaches to the Thames Estuary | N8: UKHO-labelled document on third-party host; edition and currency unverified. | Q8: B01 | R8: Candidate recorded | S8: Not established
A9: TSS-0003 | B9: British Isles and southern North Sea | C9: In the Approaches to Hook of Holland and at North Hinder | D9: Source entry; component check pending | E9: Provisional: official baseline reconciliation pending | F9: Not researched | G9: Not researched | J9: Combined label. Check whether separate scheme records are required. | K9: SRC-001 | L9: https://www.scribd.com/document/1014775753/1-1-IMO-Adopted-Traffic-Separation-Schemes-on-the-ADMIRALTY-Chart-Series | M9: Notice 17; scheme label: In the Approaches to Hook of Holland and at North Hinder | N9: UKHO-labelled document on third-party host; edition and currency unverified. | Q9: B01 | R9: Candidate recorded | S9: Not established
A10: TSS-0004 | B10: British Isles and southern North Sea | C10: At West Hinder | D10: Source entry; component check pending | E10: Provisional: official baseline reconciliation pending | F10: Not researched | G10: Not researched | K10: SRC-001 | L10: https://www.scribd.com/document/1014775753/1-1-IMO-Adopted-Traffic-Separation-Schemes-on-the-ADMIRALTY-Chart-Series | M10: Notice 17; scheme label: At West Hinder | N10: UKHO-labelled document on third-party host; edition and currency unverified. | Q10: B01 | R10: Candidate recorded | S10: Not established
A11: TSS-0005 | B11: British Isles and southern North Sea | C11: In the Strait of Dover and adjacent waters | D11: Source entry; component check pending | E11: Provisional: official baseline reconciliation pending | F11: Authority evidence found | G11: Authority evidence found | H11: VTS-001 | I11: SRS-001 | K11: SRC-001 | L11: https://www.scribd.com/document/1014775753/1-1-IMO-Adopted-Traffic-Separation-Schemes-on-the-ADMIRALTY-Chart-Series | M11: Notice 17; scheme label: In the Strait of Dover and adjacent waters | N11: UKHO-labelled document on third-party host; edition and currency unverified. | O11: SRC-004; SRC-005 | P11: https://www.gov.uk/government/publications/dover-strait-crossings-channel-navigation-information-service/dover-strait-crossings-channel-navigation-information-service-cnis https://www.gov.uk/government/publications/mgn-364-mf-amendment-2-navigation-safety-traffic-separation-schemes-application-of-rule-10-and-navigation-in-the-dover-strait/mgn-364-mf-amendment-2-navigation-safety-traffic-separation-schemes-application-of-rule-10-and-navigation-in-the-dover-strait | Q11: B01 | R11: Initial association evidenced | S11: Identification screening only
A12: TSS-0006 | B12: British Isles and southern North Sea | C12: Off Casquets | D12: Source entry; component check pending | E12: Provisional: official baseline reconciliation pending | F12: Not researched | G12: Not researched | K12: SRC-001 | L12: https://www.scribd.com/document/1014775753/1-1-IMO-Adopted-Traffic-Separation-Schemes-on-the-ADMIRALTY-Chart-Series | M12: Notice 17; scheme label: Off Casquets | N12: UKHO-labelled document on third-party host; edition and currency unverified. | Q12: B02 | R12: Candidate recorded | S12: Not established
A13: TSS-0007 | B13: British Isles and southern North Sea | C13: Off Land's End, between Seven Stones and Longships | D13: Source entry; component check pending | E13: Provisional: official baseline reconciliation pending | F13: Not researched | G13: Not researched | K13: SRC-001 | L13: https://www.scribd.com/document/1014775753/1-1-IMO-Adopted-Traffic-Separation-Schemes-on-the-ADMIRALTY-Chart-Series | M13: Notice 17; scheme label: Off Land's End, between Seven Stones and Longships | N13: UKHO-labelled document on third-party host; edition and currency unverified. | Q13: B02 | R13: Candidate recorded | S13: Not established
A14: TSS-0008 | B14: British Isles and southern North Sea | C14: South of the Isles of Scilly | D14: Source entry; component check pending | E14: Provisional: official baseline reconciliation pending | F14: Not researched | G14: Not researched | K14: SRC-001 | L14: https://www.scribd.com/document/1014775753/1-1-IMO-Adopted-Traffic-Separation-Schemes-on-the-ADMIRALTY-Chart-Series | M14: Notice 17; scheme label: South of the Isles of Scilly | N14: UKHO-labelled document on third-party host; edition and currency unverified. | Q14: B02 | R14: Candidate recorded | S14: Not established
A15: TSS-0009 | B15: British Isles and southern North Sea | C15: West of the Isles of Scilly | D15: Source entry; component check pending | E15: Provisional: official baseline reconciliation pending | F15: Not researched | G15: Not researched | K15: SRC-001 | L15: https://www.scribd.com/document/1014775753/1-1-IMO-Adopted-Traffic-Separation-Schemes-on-the-ADMIRALTY-Chart-Series | M15: Notice 17; scheme label: West of the Isles of Scilly | N15: UKHO-labelled document on third-party host; edition and currency unverified. | Q15: B02 | R15: Candidate recorded | S15: Not established
A16: TSS-0010 | B16: British Isles and southern North Sea | C16: Off Fastnet Rock | D16: Source entry; component check pending | E16: Provisional: official baseline reconciliation pending | F16: Not researched | G16: Not researched | K16: SRC-001 | L16: https://www.scribd.com/document/1014775753/1-1-IMO-Adopted-Traffic-Separation-Schemes-on-the-ADMIRALTY-Chart-Series | M16: Notice 17; scheme label: Off Fastnet Rock | N16: UKHO-labelled document on third-party host; edition and currency unverified. | Q16: B02 | R16: Candidate recorded | S16: Not established
A17: TSS-0011 | B17: British Isles and southern North Sea | C17: Off Smalls | D17: Source entry; component check pending | E17: Provisional: official baseline reconciliation pending | F17: Not researched | G17: Not researched | K17: SRC-001 | L17: https://www.scribd.com/document/1014775753/1-1-IMO-Adopted-Traffic-Separation-Schemes-on-the-ADMIRALTY-Chart-Series | M17: Notice 17; scheme label: Off Smalls | N17: UKHO-labelled document on third-party host; edition and currency unverified. | Q17: B03 | R17: Candidate recorded | S17: Not established
A18: TSS-0012 | B18: British Isles and southern North Sea | C18: Off Tuskar Rock | D18: Source entry; component check pending | E18: Provisional: official baseline reconciliation pending | F18: Not researched | G18: Not researched | K18: SRC-001 | L18: https://www.scribd.com/document/1014775753/1-1-IMO-Adopted-Traffic-Separation-Schemes-on-the-ADMIRALTY-Chart-Series | M18: Notice 17; scheme label: Off Tuskar Rock | N18: UKHO-labelled document on third-party host; edition and currency unverified. | Q18: B03 | R18: Candidate recorded | S18: Not established
A19: TSS-0013 | B19: British Isles and southern North Sea | C19: Off Skerries | D19: Source entry; component check pending | E19: Provisional: official baseline reconciliation pending | F19: Not researched | G19: Not researched | K19: SRC-001 | L19: https://www.scribd.com/document/1014775753/1-1-IMO-Adopted-Traffic-Separation-Schemes-on-the-ADMIRALTY-Chart-Series | M19: Notice 17; scheme label: Off Skerries | N19: UKHO-labelled document on third-party host; edition and currency unverified. | Q19: B03 | R19: Candidate recorded | S19: Not established
A20: TSS-0014 | B20: British Isles and southern North Sea | C20: In Liverpool Bay | D20: Source entry; component check pending | E20: Provisional: official baseline reconciliation pending | F20: Not researched | G20: Not researched | K20: SRC-001 | L20: https://www.scribd.com/document/1014775753/1-1-IMO-Adopted-Traffic-Separation-Schemes-on-the-ADMIRALTY-Chart-Series | M20: Notice 17; scheme label: In Liverpool Bay | N20: UKHO-labelled document on third-party host; edition and currency unverified. | Q20: B03 | R20: Candidate recorded | S20: Not established
A21: TSS-0015 | B21: British Isles and southern North Sea | C21: In the North Channel | D21: Source entry; component check pending | E21: Provisional: official baseline reconciliation pending | F21: Not researched | G21: Not researched | K21: SRC-001 | L21: https://www.scribd.com/document/1014775753/1-1-IMO-Adopted-Traffic-Separation-Schemes-on-the-ADMIRALTY-Chart-Series | M21: Notice 17; scheme label: In the North Channel | N21: UKHO-labelled document on third-party host; edition and currency unverified. | Q21: B03 | R21: Candidate recorded | S21: Not established
A22: TSS-0016 | B22: British Isles and southern North Sea | C22: Off Neist Point | D22: Source entry; component check pending | E22: Provisional: official baseline reconciliation pending | F22: Not researched | G22: Not researched | K22: SRC-001 | L22: https://www.scribd.com/document/1014775753/1-1-IMO-Adopted-Traffic-Separation-Schemes-on-the-ADMIRALTY-Chart-Series | M22: Notice 17; scheme label: Off Neist Point | N22: UKHO-labelled document on third-party host; edition and currency unverified. | Q22: B04 | R22: Candidate recorded | S22: Not established
A23: TSS-0017 | B23: Norway and Iceland | C23: Off the coast of Norway | D23: Source entry; component check pending | E23: Provisional: official baseline reconciliation pending | F23: Not researched | G23: Not researched | J23: Grouped coastline label. Expand into named component schemes before counting. | K23: SRC-001 | L23: https://www.scribd.com/document/1014775753/1-1-IMO-Adopted-Traffic-Separation-Schemes-on-the-ADMIRALTY-Chart-Series | M23: Notice 17; scheme label: Off the coast of Norway | N23: UKHO-labelled document on third-party host; edition and currency unverified. | Q23: B04 | R23: Candidate recorded | S23: Not established
A24: TSS-0018 | B24: Norway and Iceland | C24: Off the south-west coast of Iceland: North-west of Garoskagi Point | D24: Source entry; component check pending | E24: Provisional: official baseline reconciliation pending | F24: Not researched | G24: Not researched | J24: Check official Icelandic spelling against the primary publication. | K24: SRC-001 | L24: https://www.scribd.com/document/1014775753/1-1-IMO-Adopted-Traffic-Separation-Schemes-on-the-ADMIRALTY-Chart-Series | M24: Notice 17; scheme label: Off the south-west coast of Iceland: North-west of Garoskagi Point | N24: UKHO-labelled document on third-party host; edition and currency unverified. | Q24: B04 | R24: Candidate recorded | S24: Not established
A25: TSS-0019 | B25: Norway and Iceland | C25: Off the south-west coast of Iceland: South-west of the Reykjanes Peninsula | D25: Source entry; component check pending | E25: Provisional: official baseline reconciliation pending | F25: Not researched | G25: Not researched | K25: SRC-001 | L25: https://www.scribd.com/document/1014775753/1-1-IMO-Adopted-Traffic-Separation-Schemes-on-the-ADMIRALTY-Chart-Series | M25: Notice 17; scheme label: Off the south-west coast of Iceland: South-west of the Reykjanes Peninsula | N25: UKHO-labelled document on third-party host; edition and currency unverified. | Q25: B04 | R25: Candidate recorded | S25: Not established
A26: TSS-0020 | B26: Baltic Sea and approaches | C26: The Åland Sea: North Åland Sea, South Åland Sea | D26: Source entry; component check pending | E26: Provisional: official baseline reconciliation pending | F26: Not researched | G26: Not researched | J26: Two named components appear within one source entry. Retain parent; reconcile component IDs. | K26: SRC-001 | L26: https://www.scribd.com/document/1014775753/1-1-IMO-Adopted-Traffic-Separation-Schemes-on-the-ADMIRALTY-Chart-Series | M26: Notice 17; scheme label: The Åland Sea: North Åland Sea, South Åland Sea | N26: UKHO-labelled document on third-party host; edition and currency unverified. | Q26: B04 | R26: Candidate recorded | S26: Not established
A27: TSS-0021 | B27: Baltic Sea and approaches | C27: Off Sommers Island (Ostrov Sommers) | D27: Source entry; component check pending | E27: Provisional: official baseline reconciliation pending | F27: Not researched | G27: Legacy GOFREP lead; direct association unverified | I27: SRS-006 | J27: Restored from the earlier v0.1 research leads. The checked Fintraffic pages do not identify this TSS by name. Direct authority/boundary verification is still required. | K27: SRC-001 | L27: https://www.scribd.com/document/1014775753/1-1-IMO-Adopted-Traffic-Separation-Schemes-on-the-ADMIRALTY-Chart-Series | M27: Notice 17; scheme label: Off Sommers Island (Ostrov Sommers) | N27: UKHO-labelled document on third-party host; edition and currency unverified. | O27: SRC-011; SRC-012 | P27: https://mastersguide.fintraffic.fi/en/gofrep-area https://www.fintraffic.fi/sv/node/254 | Q27: B05 | R27: Association proposed | S27: 2026-09-29
A28: TSS-0022 | B28: Baltic Sea and approaches | C28: Off Hogland (Gogland) Island (Ostrov Gogland) | D28: Source entry; component check pending | E28: Provisional: official baseline reconciliation pending | F28: Not researched | G28: Legacy GOFREP lead; direct association unverified | I28: SRS-006 | J28: Restored from the earlier v0.1 research leads. The checked Fintraffic pages do not identify this TSS by name. Direct authority/boundary verification is still required. | K28: SRC-001 | L28: https://www.scribd.com/document/1014775753/1-1-IMO-Adopted-Traffic-Separation-Schemes-on-the-ADMIRALTY-Chart-Series | M28: Notice 17; scheme label: Off Hogland (Gogland) Island (Ostrov Gogland) | N28: UKHO-labelled document on third-party host; edition and currency unverified. | O28: SRC-011; SRC-012 | P28: https://mastersguide.fintraffic.fi/en/gofrep-area https://www.fintraffic.fi/sv/node/254 | Q28: B05 | R28: Association proposed | S28: 2026-09-29
A29: TSS-0023 | B29: Baltic Sea and approaches | C29: Off Rodsher Island (Ostrov Rodsher) | D29: Source entry; component check pending | E29: Provisional: official baseline reconciliation pending | F29: Not researched | G29: Legacy GOFREP lead; direct association unverified | I29: SRS-006 | J29: Restored from the earlier v0.1 research leads. The checked Fintraffic pages do not identify this TSS by name. Direct authority/boundary verification is still required. | K29: SRC-001 | L29: https://www.scribd.com/document/1014775753/1-1-IMO-Adopted-Traffic-Separation-Schemes-on-the-ADMIRALTY-Chart-Series | M29: Notice 17; scheme label: Off Rodsher Island (Ostrov Rodsher) | N29: UKHO-labelled document on third-party host; edition and currency unverified. | O29: SRC-011; SRC-012 | P29: https://mastersguide.fintraffic.fi/en/gofrep-area https://www.fintraffic.fi/sv/node/254 | Q29: B05 | R29: Association proposed | S29: 2026-09-29
A30: TSS-0024 | B30: Baltic Sea and approaches | C30: Off Kalbådagrund Lighthouse | D30: Source entry; component check pending | E30: Provisional: official baseline reconciliation pending | F30: Not established by reporting source | G30: Authority evidence found | I30: SRS-006 | K30: SRC-001 | L30: https://www.scribd.com/document/1014775753/1-1-IMO-Adopted-Traffic-Separation-Schemes-on-the-ADMIRALTY-Chart-Series | M30: Notice 17; scheme label: Off Kalbådagrund Lighthouse | N30: UKHO-labelled document on third-party host; edition and currency unverified. | O30: SRC-011; SRC-012 | P30: https://mastersguide.fintraffic.fi/en/gofrep-area https://www.fintraffic.fi/sv/node/254 | Q30: B05 | R30: Initial association evidenced | S30: Identification screening only
A31: TSS-0025 | B31: Baltic Sea and approaches | C31: Off Porkkala Lighthouse | D31: Source entry; component check pending | E31: Provisional: official baseline reconciliation pending | F31: Not established by reporting source | G31: Authority evidence found | I31: SRS-006 | K31: SRC-001 | L31: https://www.scribd.com/document/1014775753/1-1-IMO-Adopted-Traffic-Separation-Schemes-on-the-ADMIRALTY-Chart-Series | M31: Notice 17; scheme label: Off Porkkala Lighthouse | N31: UKHO-labelled document on third-party host; edition and currency unverified. | O31: SRC-011; SRC-012 | P31: https://mastersguide.fintraffic.fi/en/gofrep-area https://www.fintraffic.fi/sv/node/254 | Q31: B05 | R31: Initial association evidenced | S31: Identification screening only
A32: TSS-0026 | B32: Baltic Sea and approaches | C32: Off Hankoniemi Peninsula (Hanko) | D32: Source entry; component check pending | E32: Provisional: official baseline reconciliation pending | F32: Not established by reporting source | G32: Authority evidence found | I32: SRS-006 | K32: SRC-001 | L32: https://www.scribd.com/document/1014775753/1-1-IMO-Adopted-Traffic-Separation-Schemes-on-the-ADMIRALTY-Chart-Series | M32: Notice 17; scheme label: Off Hankoniemi Peninsula (Hanko) | N32: UKHO-labelled document on third-party host; edition and currency unverified. | O32: SRC-011; SRC-012 | P32: https://mastersguide.fintraffic.fi/en/gofrep-area https://www.fintraffic.fi/sv/node/254 | Q32: B06 | R32: Initial association evidenced | S32: Identification screening only
A33: TSS-0027 | B33: Baltic Sea and approaches | C33: Off Köpu Peninsula (Hiiumaa Island) | D33: Source entry; component check pending | E33: Provisional: official baseline reconciliation pending | F33: Not established by reporting source | G33: Authority evidence found | I33: SRS-006 | K33: SRC-001 | L33: https://www.scribd.com/document/1014775753/1-1-IMO-Adopted-Traffic-Separation-Schemes-on-the-ADMIRALTY-Chart-Series | M33: Notice 17; scheme label: Off Köpu Peninsula (Hiiumaa Island) | N33: UKHO-labelled document on third-party host; edition and currency unverified. | O33: SRC-011; SRC-012 | P33: https://mastersguide.fintraffic.fi/en/gofrep-area https://www.fintraffic.fi/sv/node/254 | Q33: B06 | R33: Initial association evidenced | S33: Identification screening only
A34: TSS-0028 | B34: Baltic Sea and approaches | C34: North Hoburgs Bank | D34: Source entry; component check pending | E34: Provisional: official baseline reconciliation pending | F34: Not researched | G34: Not researched | K34: SRC-001 | L34: https://www.scribd.com/document/1014775753/1-1-IMO-Adopted-Traffic-Separation-Schemes-on-the-ADMIRALTY-Chart-Series | M34: Notice 17; scheme label: North Hoburgs Bank | N34: UKHO-labelled document on third-party host; edition and currency unverified. | Q34: B06 | R34: Candidate recorded | S34: Not established
A35: TSS-0029 | B35: Baltic Sea and approaches | C35: South Hoburgs Bank | D35: Source entry; component check pending | E35: Provisional: official baseline reconciliation pending | F35: Not researched | G35: Not researched | K35: SRC-001 | L35: https://www.scribd.com/document/1014775753/1-1-IMO-Adopted-Traffic-Separation-Schemes-on-the-ADMIRALTY-Chart-Series | M35: Notice 17; scheme label: South Hoburgs Bank | N35: UKHO-labelled document on third-party host; edition and currency unverified. | Q35: B06 | R35: Candidate recorded | S35: Not established
A36: TSS-0030 | B36: Baltic Sea and approaches | C36: West Klintehamn | D36: Source entry; component check pending | E36: Provisional: official baseline reconciliation pending | F36: Not researched | G36: Not researched | K36: SRC-001 | L36: https://www.scribd.com/document/1014775753/1-1-IMO-Adopted-Traffic-Separation-Schemes-on-the-ADMIRALTY-Chart-Series | M36: Notice 17; scheme label: West Klintehamn | N36: UKHO-labelled document on third-party host; edition and currency unverified. | Q36: B06 | R36: Candidate recorded | S36: Not established
A37: TSS-0031 | B37: Baltic Sea and approaches | C37: Midsjöbankarna | D37: Source entry; component check pending | E37: Provisional: official baseline reconciliation pending | F37: Not researched | G37: Not researched | K37: SRC-001 | L37: https://www.scribd.com/document/1014775753/1-1-IMO-Adopted-Traffic-Separation-Schemes-on-the-ADMIRALTY-Chart-Series | M37: Notice 17; scheme label: Midsjöbankarna | N37: UKHO-labelled document on third-party host; edition and currency unverified. | Q37: B07 | R37: Candidate recorded | S37: Not established
A38: TSS-0032 | B38: Baltic Sea and approaches | C38: Adlergrund | D38: Source entry; component check pending | E38: Provisional: official baseline reconciliation pending | F38: Not researched | G38: Not researched | K38: SRC-001 | L38: https://www.scribd.com/document/1014775753/1-1-IMO-Adopted-Traffic-Separation-Schemes-on-the-ADMIRALTY-Chart-Series | M38: Notice 17; scheme label: Adlergrund | N38: UKHO-labelled document on third-party host; edition and currency unverified. | Q38: B07 | R38: Candidate recorded | S38: Not established
A39: TSS-0033 | B39: Baltic Sea and approaches | C39: Slupska Bank | D39: Source entry; component check pending | E39: Provisional: official baseline reconciliation pending | F39: Not researched | G39: Not researched | J39: Check component names and amendments; do not assume this label represents one current scheme. | K39: SRC-001 | L39: https://www.scribd.com/document/1014775753/1-1-IMO-Adopted-Traffic-Separation-Schemes-on-the-ADMIRALTY-Chart-Series | M39: Notice 17; scheme label: Slupska Bank | N39: UKHO-labelled document on third-party host; edition and currency unverified. | Q39: B07 | R39: Candidate recorded | S39: Not established
A40: TSS-0034 | B40: Baltic Sea and approaches | C40: Off Öland Island | D40: Source entry; component check pending | E40: Provisional: official baseline reconciliation pending | F40: Not researched | G40: Not researched | K40: SRC-001 | L40: https://www.scribd.com/document/1014775753/1-1-IMO-Adopted-Traffic-Separation-Schemes-on-the-ADMIRALTY-Chart-Series | M40: Notice 17; scheme label: Off Öland Island | N40: UKHO-labelled document on third-party host; edition and currency unverified. | Q40: B07 | R40: Candidate recorded | S40: Not established
A41: TSS-0035 | B41: Baltic Sea and approaches | C41: In Bornholmsgat | D41: Source entry; component check pending | E41: Provisional: official baseline reconciliation pending | F41: Not researched | G41: Not researched | K41: SRC-001 | L41: https://www.scribd.com/document/1014775753/1-1-IMO-Adopted-Traffic-Separation-Schemes-on-the-ADMIRALTY-Chart-Series | M41: Notice 17; scheme label: In Bornholmsgat | N41: UKHO-labelled document on third-party host; edition and currency unverified. | Q41: B07 | R41: Candidate recorded | S41: Not established
A42: TSS-0036 | B42: Baltic Sea and approaches | C42: North of Rügen | D42: Source entry; component check pending | E42: Provisional: official baseline reconciliation pending | F42: Not researched | G42: Not researched | K42: SRC-001 | L42: https://www.scribd.com/document/1014775753/1-1-IMO-Adopted-Traffic-Separation-Schemes-on-the-ADMIRALTY-Chart-Series | M42: Notice 17; scheme label: North of Rügen | N42: UKHO-labelled document on third-party host; edition and currency unverified. | Q42: B08 | R42: Candidate recorded | S42: Not established
A43: TSS-0037 | B43: Baltic Sea and approaches | C43: South of Gedser | D43: Source entry; component check pending | E43: Provisional: official baseline reconciliation pending | F43: Not researched | G43: Not researched | K43: SRC-001 | L43: https://www.scribd.com/document/1014775753/1-1-IMO-Adopted-Traffic-Separation-Schemes-on-the-ADMIRALTY-Chart-Series | M43: Notice 17; scheme label: South of Gedser | N43: UKHO-labelled document on third-party host; edition and currency unverified. | Q43: B08 | R43: Candidate recorded | S43: Not established
...

Sheet Stage 4 Findings
A1: STAGE 4 FINDINGS | B10 TO B34
A3: v0.3 | First-pass record research. Findings are research determinations, not operational guidance. Unresolved never means absent.
A6: Record ID | B6: Batch | C6: Group | D6: Source label | E6: Official name | F6: States | G6: TSS identity | H6: Identity note | I6: Operational status | J6: Components | K6: VTS finding | L6: VTS service IDs | M6: VTS basis | N6: Reporting finding | O6: Reporting scheme IDs | P6: Reporting basis | Q6: Voluntary reporting | R6: Applicability notes | S6: Provisional complexity | T6: Complexity reason | U6: Source IDs | V6: Open questions | W6: Audit adjustments at merge
A7: TSS-0046 | B7: B10 | C7: A | D7: German Bight Western Approach | E7: German Bight western approach | F7: Germany | G7: Confirmed | H7: Named in IMO COLREG.2/Circ.59 (MSC 83, 2007) as amended scheme with special provisions for the North Hinder to German Bight tanker route, implemented 1 May 2008 (S1); listed in IMO Ships' Routeing 2008 (S27) and Transportstyrelsen 2017 list (S4). German statute designates it a deep-water route (Tiefwasserweg) mandatory for large tankers (S6 Nr. 6). MSC 109 adopted a revised containership recommendation covering it from 1 July 2025 (lead S5). No evidence of renaming or restructuring by recent IMO amendments was found. | I7: In force | K7: Confirmed present | L7: VTS-016 | M7: AnlBV Anlage Nr. 3.1 requires ships approaching the Inner German Bight from the west to report to 'German Bight Traffic' at 007° 10' E 'unabhängig davon, ob das Verkehrstrennungsgebiet German Bight Western Approach benutzt wird' (S6); Nr. 5.1 states traffic is monitored under maritime traffic safety. Coverage evidenced for the eastern part of the scheme and its approach into the Inner German Bight; the western extent of the scheme relative to the VTS area was not verified. | N7: Unresolved | P7: National mandatory report (AnlBV Nr. 3.1) at 007° 10' E for ships and tows over 300 GT, expressly regardless of use of this TSS (S6). Not an IMO-adopted SRS. | R7: Report: over 300 GT. Mandatory use of the TSS (AnlBV Nr. 6): oil tankers over 10,000 GT, NLS Z tankers over 10,000 GT, NLS X/Y tankers over 5,000 GT, gas tankers over 10,000 GT approaching or leaving the Inner German Bight from the west. Mandatory route for tankers from North Hinder to the German Bight applies to oil tankers 10,000 GT and over, chemical/NLS tankers 5,000 GT (X/Y) or 10,000 GT (Z) and over, and gas carriers 10,000 GT and over (S1, annex 4). Reports under AnlBV Anlage Nr. 3.1 and SeeSchStrO section 58 are made to German Bight Traffic, a VTS. Recorded under the service as VTS reporting duties (national statute, not an IMO-adopted scheme). | S7: Complex | T7: National mandatory reporting plus national mandatory-use rule, IMO mandatory tanker route and 2025 containership recommendation overlap; cross-border Dutch/German routeing context. | U7: SRC-024; SRC-027; SRC-028; SRC-029; SRC-031; SRC-033; SRC-034; SRC-050 | V7: Exact westward extent of the scheme and whether any part lies in Netherlands waters not verified. IMO text of the 2024 containership recommendation (MSC 109) not retrieved. No evidence found of any recent IMO renaming of German TSS, but Circ. texts after 2016 were not all retrieved. | W7: reporting_finding: Confirmed present -> Unresolved. Reports under AnlBV Anlage Nr. 3.1 and SeeSchStrO section 58 are made to German Bight Traffic, a VTS. Recorded under the service as VTS reporting duties (national statute, not an IMO-adopted scheme). No separate mandatory scheme evidenced.
A8: TSS-0047 | B8: B10 | C8: A | D8: Elbe Approach | E8: Elbe approach | F8: Germany | G8: Confirmed | H8: Listed as 'Elbe approach' in IMO Ships' Routeing 2008 (S27) and the Transportstyrelsen 2017 list of IMO schemes (S4). Adopting and latest amending circular not retrieved. | I8: In force | K8: Confirmed present | L8: VTS-018; VTS-016 | M8: Cuxhaven VTS is responsible for the Elbe 'im Bereich der Elbeansteuerung' (Elbe approach) (S9); the GDWS Bekanntmachung sets the Cuxhaven Elbe Traffic area from buoy Nordergründe-Nord (008° E), with outbound reports there to German Bight Traffic on VHF 80 (S7). Coverage is of the direct approach; the TSS lanes themselves are in the Inner German Bight covered by German Bight Traffic, but the exact TSS-to-sector boundary was not verified. | N8: Unresolved | P8: SeeSchStrO § 58 position report at NGN (008° E) to Cuxhaven Elbe Traffic inbound and German Bight Traffic outbound (S7); AnlBV Nr. 3.1 entry report for ships entering the Inner German Bight from west or north (S6). National, not IMO. | R8: SeeSchStrO § 58: vessels of 50 m LOA or more and ships under § 30(1). AnlBV: over 300 GT. SeeSchStrO section 58 reports on the Elbe approach are made to the VTS centres. Recorded under the service as VTS reporting duties. Reports under AnlBV Anlage Nr. 3.1 and SeeSchStrO section 58 are made to German Bight Traffic, a VTS. Recorded under the service as VTS reporting duties (national statute, not an IMO-adopted scheme). | S8: Intermediate | T8: Two VTS services and two national reporting regimes meet at the seaward end of the Elbe. | U8: SRC-027; SRC-029; SRC-030; SRC-032; SRC-033; SRC-050 | V8: Adopting IMO instrument and current chart geometry not retrieved; confirm whether the TSS lies seaward of NGN (German Bight Traffic sector) or partly within Cuxhaven Elbe Traffic sector. | W8: reporting_finding: Confirmed present -> Unresolved. SeeSchStrO section 58 reports on the Elbe approach are made to the VTS centres. Recorded under the service as VTS reporting duties. Reports under AnlBV Anlage Nr. 3.1 and SeeSchStrO section 58 are made to German Bight Traffic, a VTS. Recorded under the service as VTS reporting duties (national statute, not an IMO-adopted scheme). No separate mandatory scheme evidenced.
A9: TSS-0048 | B9: B10 | C9: A | D9: Jade Approach | E9: Jade approach | F9: Germany | G9: Confirmed | H9: Listed as 'Jade approach' in IMO Ships' Routeing 2008 (S27) and Transportstyrelsen 2017 list (S4). WSV describes it as the link between Terschelling-German Bight and the Western Approach giving access to Weser and Jade from the north (S11). German statute places a pilot transfer position 'im Verkehrstrennungsgebiet Jade Approach' within the Inner German Bight (S6 Nr. 8). | I9: In force | K9: Confirmed present | L9: VTS-016 | M9: AnlBV Nr. 8 locates the scheme in the Inner German Bight outside the territorial sea; Nr. 5.1 states traffic there is monitored under maritime traffic safety and Nr. 3.1 routes reports to German Bight Traffic (S6). German Bight Traffic monitors the inner German Bight from Borkum to Helgoland (S8). | N9: Unresolved | P9: AnlBV Nr. 3.1 report at 54° 20' N or 007° 10' E; SeeSchStrO § 58 entry report at 54° 15' N west of Helgoland to German Bight Traffic (S6, S7). | R9: AnlBV: over 300 GT. SeeSchStrO § 58: 50 m or more. Compulsory pilotage from the Jade Approach transfer position for large tankers, bulk carriers and other ships per AnlBV Nr. 8 (S6). Reports under AnlBV Anlage Nr. 3.1 and SeeSchStrO section 58 are made to German Bight Traffic, a VTS. Recorded under the service as VTS reporting duties (national statute, not an IMO-adopted scheme). | S9: Intermediate | T9: National reporting, VTS and offshore pilotage obligations combine; single VTS. | U9: SRC-027; SRC-029; SRC-030; SRC-031; SRC-034; SRC-050 | V9: Adopting IMO instrument and any recent amendments not retrieved. | W9: reporting_finding: Confirmed present -> Unresolved. Reports under AnlBV Anlage Nr. 3.1 and SeeSchStrO section 58 are made to German Bight Traffic, a VTS. Recorded under the service as VTS reporting duties (national statute, not an IMO-adopted scheme). No separate mandatory scheme evidenced.
A10: TSS-0049 | B10: B10 | C10: A | D10: Terschelling - German Bight | E10: Terschelling-German Bight | F10: Netherlands; Germany | G10: Confirmed | H10: Amended by COLREG.2/Circ.59 (MSC 83, implemented 1 May 2008) (S1); listed in Ships' Routeing 2008 (S27) and Transportstyrelsen 2017 list (S4). MSC 109 containership recommendation from 1 July 2025 (lead S5). | I10: In force | K10: Confirmed present | L10: VTS-016 | M10: Bekanntmachung 19.1.4 and 19.1.5 require vessels using the TSS 'Terschelling - German Bight' and its inshore traffic zone to report to German Bight Traffic at Borkumriff buoy (VHF 79) and at TG 17/C eastbound (VHF 80) (S7). This establishes coverage of the German (eastern) part only. For the Dutch part: No Dutch VTS was found whose defined area covers this offshore scheme. The Netherlands Coastguard performs Vessel Traffic Monitoring (VTMon) and distinguishes VTS as provided by traffic centres (S14, S15); VTMon is recorded as a lead only, not as a VTS. | N10: Unresolved | P10: SeeSchStrO § 58 entry and position reports (vessels 50 m or more) and AnlBV Nr. 3.1 (over 300 GT) apply on the German part (S6, S7). National, not IMO. No mandatory reporting identified for the Dutch part. | Q10: Netherlands Coastguard broadcasts wave-height advice for container ships in TSS Terschelling-German Bight and may advise the northern route; advice is not binding (S13). | R10: Mandatory route for tankers from North Hinder to the German Bight applies to oil tankers 10,000 GT and over, chemical/NLS tankers 5,000 GT (X/Y) or 10,000 GT (Z) and over, and gas carriers 10,000 GT and over (S1, annex 4). Coastguard advice targets container ships 100 to 200 m at 3 m waves and over 200 m at 4 m waves (S13). Reports under AnlBV Anlage Nr. 3.1 and SeeSchStrO section 58 are made to German Bight Traffic, a VTS. Recorded under the service as VTS reporting duties (national statute, not an IMO-adopted scheme). | S10: Complex | T10: Cross-border scheme: German VTS and national reporting on eastern part, no VTS evidenced on Dutch part, plus mandatory tanker route and containership advice. | U10: SRC-024; SRC-027; SRC-028; SRC-029; SRC-030; SRC-031; SRC-034; SRC-036; SRC-037; SRC-038; SRC-050 | V10: Exact boundary between German Bight Traffic coverage and the Dutch part not verified. Rijkswaterstaat Brandaris (Terschelling) VTS designation could not be read (officielebekendmakingen.nl returned HTTP 403); search snippets indicate its area is the Terschelling zeegat approach, not the TSS. | W10: reporting_finding: Confirmed present -> Unresolved. Reports under AnlBV Anlage Nr. 3.1 and SeeSchStrO section 58 are made to German Bight Traffic, a VTS. Recorded under the service as VTS reporting duties (national statute, not an IMO-adopted scheme). No separate mandatory scheme evidenced.
A11: TSS-0050 | B11: B10 | C11: A | D11: Vlieland North | E11: Vlieland North (part of 'Off Vlieland, Vlieland North and Vlieland Junction') | F11: Netherlands | G11: Confirmed | H11: COLREG.2/Circ.59 (MSC 83, implemented 1 May 2008) amended the special provisions of 'Off Vlieland, Vlieland North and Vlieland Junction' (S1). IMO Ships' Routeing 2008 treats these as one routeing system entry (S27). Component of the same system as TSS-0051. | I11: In force | J11: Off Vlieland; Vlieland North; Vlieland Junction | K11: Unresolved | M11: No Dutch VTS was found whose defined area covers this offshore scheme. The Netherlands Coastguard performs Vessel Traffic Monitoring (VTMon) and distinguishes VTS as provided by traffic centres (S14, S15); VTMon is recorded as a lead only, not as a VTS. | N11: Unresolved | P11: No IMO-adopted mandatory ship reporting system or national mandatory reporting specific to this scheme was found. Netherlands Coastguard states it 'has no powers to impose traffic directions' (S13). A failed search is not proof of absence. | R11: Mandatory route for tankers from North Hinder to the German Bight applies to oil tankers 10,000 GT and over, chemical/NLS tankers 5,000 GT (X/Y) or 10,000 GT (Z) and over, and gas carriers 10,000 GT and over (S1, annex 4). | S11: Intermediate | T11: Part of a multi-component routeing system linked to the IMO mandatory tanker route; no VTS or reporting identified. | U11: SRC-024; SRC-027; SRC-036; SRC-037; SRC-038; SRC-050 | V11: Duplicate/grouping: likely to merge with TSS-0051 under 'Off Vlieland, Vlieland North and Vlieland Junction'. Current Dutch legal text (puc.overheid.nl) returned HTTP 403.
A12: TSS-0051 | B12: B11 | C12: A | D12: Off Vlieland | E12: Off Vlieland (part of 'Off Vlieland, Vlieland North and Vlieland Junction') | F12: Netherlands | G12: Confirmed | H12: As TSS-0050: amended by COLREG.2/Circ.59, implemented 1 May 2008 (S1); single entry in Ships' Routeing 2008 (S27). MSC 109 containership recommendation covers 'Off Vlieland' from 1 July 2025 (lead S5). | I12: In force | J12: Off Vlieland; Vlieland North; Vlieland Junction | K12: Unresolved | M12: No Dutch VTS was found whose defined area covers this offshore scheme. The Netherlands Coastguard performs Vessel Traffic Monitoring (VTMon) and distinguishes VTS as provided by traffic centres (S14, S15); VTMon is recorded as a lead only, not as a VTS. | N12: Unresolved | P12: No IMO-adopted mandatory ship reporting system or national mandatory reporting specific to this scheme was found. Netherlands Coastguard states it 'has no powers to impose traffic directions' (S13). A failed search is not proof of absence. | Q12: Coastguard container-ship wave advice applies to the southern route north of the West Frisian Islands (S13); relationship to this specific scheme not stated. | R12: Mandatory route for tankers from North Hinder to the German Bight applies to oil tankers 10,000 GT and over, chemical/NLS tankers 5,000 GT (X/Y) or 10,000 GT (Z) and over, and gas carriers 10,000 GT and over (S1, annex 4). | S12: Intermediate | T12: Multi-component system, mandatory tanker route and containership recommendation; no VTS identified. | U12: SRC-024; SRC-027; SRC-028; SRC-036; SRC-037; SRC-038; SRC-050 | V12: Merge with TSS-0050. Text of the 2024 containership recommendation not retrieved.
A13: TSS-0052 | B13: B11 | C13: A | D13: Off Texel | E13: Off Texel | F13: Netherlands | G13: Confirmed | H13: Amended by COLREG.2/Circ.59 (implemented 1 May 2008) (S1); further amended by COLREG.2/Circ.64 (MSC 91, 2012), implemented 1 August 2013, per the Transportstyrelsen list (S4); Circ.64 text itself not retrieved. | I13: In force | K13: Unresolved | M13: No Dutch VTS was found whose defined area covers this offshore scheme. The Netherlands Coastguard performs Vessel Traffic Monitoring (VTMon) and distinguishes VTS as provided by traffic centres (S14, S15); VTMon is recorded as a lead only, not as a VTS. Den Helder port VTS not researched for coverage of this scheme. | N13: Unresolved | P13: No IMO-adopted mandatory ship reporting system or national mandatory reporting specific to this scheme was found. Netherlands Coastguard states it 'has no powers to impose traffic directions' (S13). A failed search is not proof of absence. | R13: Mandatory route for tankers from North Hinder to the German Bight applies to oil tankers 10,000 GT and over, chemical/NLS tankers 5,000 GT (X/Y) or 10,000 GT (Z) and over, and gas carriers 10,000 GT and over (S1, annex 4). | S13: Intermediate | T13: Linked to IMO mandatory tanker route; 2013 restructuring of Dutch routeing. | U13: SRC-024; SRC-027; SRC-037; SRC-038 | V13: Retrieve COLREG.2/Circ.64 (NOAA copy redirects; IMO copy not found). Check Den Helder VTS area against the scheme.
A14: TSS-0053 | B14: B11 | C14: A | D14: In the Approaches to IJmuiden | E14: In the approaches to IJmuiden | F14: Netherlands | G14: Confirmed | H14: New scheme adopted by MSC 91 and circulated as COLREG.2/Circ.64 (2012), implemented 1 August 2013, per Transportstyrelsen list (S4); associated precautionary areas in SN.1/Circ.317 (S4). Separate IMO deep-water route leading to IJmuiden listed in Ships' Routeing 2008 (S27). Circ.64 text not retrieved. | I14: In force | K14: Unresolved | L14: VTS-019 | M14: VTS North Sea Canal Area covers 'the approaches to IJmuiden ... within a 12-nautical-mile radius ... including the extended IJ-geul deep water channel' (S12). The source does not state that the TSS lanes lie within this area; the extended IJ-geul is a separate IMO deep-water route. VTS named as a strong lead; overlap with the TSS needs chart verification. | N14: Unresolved | P14: No IMO or national mandatory reporting system specific to the TSS found. Within the VTS area there are ordinary VTS reporting duties: report on arrival at 12 nm to Sector IJmuiden VHF 61 and to IJmuiden Approaches VHF 07 'as soon as VHF contact is possible' (S12). These are VTS reporting duties, recorded separately. | R14: VTS reporting and listening watch apply to vessels in the VTS area per S12. | S14: Intermediate | T14: TSS, deep-water route, precautionary areas and a port VTS with sector structure; overlap to be confirmed. | U14: SRC-027; SRC-035; SRC-050 | V14: Retrieve Circ.64 annex or chart INT 1418 to test whether any TSS lane lies within 12 nm of the breakwaters or on the extended IJ-geul. Dutch 2020 to 2023 Notices to Mariners (defensie.nl) returned 404.
A15: TSS-0054 | B15: B11 | C15: A | D15: Off Brown Ridge | F15: Netherlands (presumed) | G15: Provisional | H15: Existence of a TSS 'Off Brown Ridge' is indicated only by leads: Wikipedia list 'Brown Ridge' (S30) and search snippets describing a deep-water route linking TSS Off Brown Ridge to TSS West Friesland and the 1 August 2013 Dutch re-routeing. Not found in Ships' Routeing 2008 contents (S27) or Transportstyrelsen 2017 list (S4) as a separate entry; may be a component of 'Off Friesland' or of the 2013 Dutch routeing package. Adopting instrument not retrieved. | I15: Not established | K15: Unresolved | M15: No Dutch VTS was found whose defined area covers this offshore scheme. The Netherlands Coastguard performs Vessel Traffic Monitoring (VTMon) and distinguishes VTS as provided by traffic centres (S14, S15); VTMon is recorded as a lead only, not as a VTS. | N15: Unresolved | P15: No IMO-adopted mandatory ship reporting system or national mandatory reporting specific to this scheme was found. Netherlands Coastguard states it 'has no powers to impose traffic directions' (S13). A failed search is not proof of absence. | R15: Search snippet (lead) states it forms part of a mandatory route for some classes of vessels; not verified. | S15: Not assessed | T15: Identity not confirmed. | U15: SRC-027; SRC-050; SRC-053 | V15: Identify adopting instrument (possibly COLREG.2/Circ.64 or a 2012/2013 Dutch package); Dutch official texts on puc.overheid.nl blocked (HTTP 403); Dutch NtM 2017 no.183 returned 404.
A16: TSS-0055 | B16: B11 | C16: A | D16: West Friesland | E16: West Friesland scheme (part of routeing system 'Off Friesland') | F16: Netherlands | G16: Confirmed | H16: Component of the 'Off Friesland' routeing system; amended by COLREG.2/Circ.66 (MSC 94, 21 November 2014), implemented 1 June 2015 (S2), corrected by COLREG.2/Circ.66/Corr.1 (MSC 96, 2016, immediate effect) (S3). MSC 109 containership recommendation covers 'Off Friesland' from 1 July 2025 (lead S5). | I16: In force | J16: West Friesland; North Friesland; East Friesland; Off Botney Ground (per S1); deep-water routes of 'Off Friesland' | K16: Unresolved | M16: No Dutch VTS was found whose defined area covers this offshore scheme. The Netherlands Coastguard performs Vessel Traffic Monitoring (VTMon) and distinguishes VTS as provided by traffic centres (S14, S15); VTMon is recorded as a lead only, not as a VTS. | N16: Unresolved | P16: No IMO-adopted mandatory ship reporting system or national mandatory reporting specific to this scheme was found. Netherlands Coastguard states it 'has no powers to impose traffic directions' (S13). A failed search is not proof of absence. | R16: Western route of Off Friesland is strongly recommended for deep-draught tankers exempted from the southern part of the mandatory tanker route (S1). | S16: Intermediate | T16: Component of a multi-scheme routeing system with deep-water routes and tanker routeing provisions. | U16: SRC-024; SRC-025; SRC-026; SRC-028; SRC-037; SRC-038 | V16: Grouping: TSS-0055, TSS-0056, TSS-0057 and TSS-0058 appear to be components of the single IMO routeing system 'Off Friesland'; consider merging.
A17: TSS-0056 | B17: B12 | C17: A | D17: North Friesland | E17: North Friesland scheme (part of routeing system 'Off Friesland') | F17: Netherlands | G17: Confirmed | H17: Established within 'Off Friesland' by COLREG.2/Circ.66 (implemented 1 June 2015), with separation zones around 54° 00' to 54° 05' N, 004° 40' to 005° 06' E (S2, S3). Dutch offshore scheme, not the German North Frisian coast. Lead (search summary) says it replaced the Friesland Junction precautionary area; not verified in retrieved text. | I17: In force | J17: West Friesland; North Friesland; East Friesland | K17: Unresolved | M17: No Dutch VTS was found whose defined area covers this offshore scheme. The Netherlands Coastguard performs Vessel Traffic Monitoring (VTMon) and distinguishes VTS as provided by traffic centres (S14, S15); VTMon is recorded as a lead only, not as a VTS. | N17: Unresolved | P17: No IMO-adopted mandatory ship reporting system or national mandatory reporting specific to this scheme was found. Netherlands Coastguard states it 'has no powers to impose traffic directions' (S13). A failed search is not proof of absence. | S17: Intermediate | T17: Component of multi-scheme routeing system. | U17: SRC-025; SRC-026; SRC-037; SRC-038 | V17: Merge with TSS-0055/0057. Confirm fate of Friesland Junction precautionary area.
A18: TSS-0057 | B18: B12 | C18: A | D18: East Friesland | E18: East Friesland scheme (part of routeing system 'Off Friesland') | F18: Netherlands | G18: Confirmed | H18: Amended within 'Off Friesland' by COLREG.2/Circ.66 (implemented 1 June 2015) and Corr.1 (2016) (S2, S3). Dutch offshore scheme around 54° 02' to 54° 06' N, 005° 08' to 005° 10' E at its western boundary; not the German East Frisian coast. | I18: In force | J18: West Friesland; North Friesland; East Friesland | K18: Unresolved | M18: No Dutch VTS was found whose defined area covers this offshore scheme. The Netherlands Coastguard performs Vessel Traffic Monitoring (VTMon) and distinguishes VTS as provided by traffic centres (S14, S15); VTMon is recorded as a lead only, not as a VTS. | N18: Unresolved | P18: No IMO-adopted mandatory ship reporting system or national mandatory reporting specific to this scheme was found. Netherlands Coastguard states it 'has no powers to impose traffic directions' (S13). A failed search is not proof of absence. | S18: Intermediate | T18: Component of multi-scheme routeing system. | U18: SRC-025; SRC-026; SRC-037; SRC-038 | V18: Merge with TSS-0055/0056. Eastern extent (toward German EEZ) not verified.
A19: TSS-0058 | B19: B12 | C19: A | D19: Off Botney Ground | E19: Off Botney Ground (part of western route of routeing system 'Off Friesland') | F19: Netherlands (presumed; UK/NL boundary area not verified) | G19: Confirmed | H19: COLREG.2/Circ.59 names 'TSS Off Botney Ground' as part of the alternative western route of the routeing system 'Off Friesland' for deep-draught tankers (S1). Not a separate entry in Ships' Routeing 2008 contents (S27). Currency after 2015 not separately verified. | I19: In force | K19: Unresolved | M19: No Dutch VTS was found whose defined area covers this offshore scheme. The Netherlands Coastguard performs Vessel Traffic Monitoring (VTMon) and distinguishes VTS as provided by traffic centres (S14, S15); VTMon is recorded as a lead only, not as a VTS. | N19: Unresolved | P19: No IMO-adopted mandatory ship reporting system or national mandatory reporting specific to this scheme was found. Netherlands Coastguard states it 'has no powers to impose traffic directions' (S13). A failed search is not proof of absence. | R19: Deep-draught tankers exempted from the southern part of the mandatory tanker route are 'strongly recommended' to use this western route and log the deviation (S1). | S19: Intermediate | T19: Offshore component linked to tanker routeing provisions; State responsibility to confirm. | U19: SRC-024; SRC-050; SRC-053 | V19: Confirm coordinates and responsible State; confirm whether still in force after the 2015 Off Friesland amendments. Consider grouping with Off Friesland records.
A20: TSS-0059 | B20: B12 | C20: A | D20: Off Ushant (Île d'Ouessant) | E20: Off Ushant | F20: France | G20: Confirmed | H20: Amended by COLREG.2/Circ.51 (MSC 75), implemented 1 May 2003 (S18); further amended by COLREG.2/Circ.64 (MSC 91), implemented 1 June 2013 per search result (Circ.64 text not retrieved). French ministry 2024 confirms DST Ouessant under CROSS Corsen (S19). | I20: In force | K20: Confirmed present | L20: VTS-021 | M20: IMO MSC.52(66): OUESSREP area 'covers a circular area 35 miles in radius centred on the Ile d'Ouessant' and 'The TSS covers the entire area'; shore authority is the Corsen/Ouessant VTS 'Ushant Traffic' at CROSS Corsen, VHF 13 (S16). French ministry 2024: 'DST Ouessant : zone de compétences CROSS Corsen' (S19). | N20: Confirmed present | O20: SRS-009 | P20: OUESSREP, IMO-adopted SOLAS mandatory ship reporting system (MSC.52(66), amended MSC.251(83) in force 1 May 2008) covering the TSS (S16, S17); French 2024 publication confirms Channel CROSS monitor ships over 300 UMS 'soumis à un compte rendu obligatoire' (S19). | R20: Ships of more than 300 GRT (S16). Report content amended 2008 to include bunker quantity for ships carrying over 5,000 t bunkers (S17). | S20: Intermediate | T20: Single VTS with IMO mandatory reporting; well documented. | U20: SRC-039; SRC-040; SRC-041; SRC-042 | V20: A current CROSS Corsen or Premar Atlantique page with VHF channels was not retrieved; channels are from the 1996 IMO text.
A21: TSS-0060 | B21: B12 | C21: A | D21: Off Finisterre | E21: Off Finisterre | F21: Spain | G21: Confirmed | H21: Originally adopted by A.767(18) (cited in S20); amended by A.957(23), implemented 1 June 2004, adding lanes for ships carrying dangerous or pollutant cargoes in bulk (S21). Listed in Ships' Routeing 2008 (S27). | I21: In force | K21: Confirmed present | L21: VTS-022 | M21: MSC.63(67): FINREP area 'includes the traffic separation scheme "off Finisterre"' and ships 'shall report to the Finisterre Traffic VTS' (S20). The amended 2004 outer southbound lane reaches 010° 13.7' W (S21), slightly west of the 1996 FINREP limit (010° 10' W), so coverage of the outermost lane is not evidenced. | N21: Confirmed present | O21: SRS-010 | P21: FINREP, IMO-adopted mandatory SRS in force 3 June 1997 (S20). | R21: FINREP: ships of 50 m LOA or more; ships carrying hazardous or potentially polluting cargo; tows over 50 m; smaller vessels fishing in or using lanes in emergency (S20). Dangerous cargo ships use designated outer lanes (S21). | S21: Intermediate | T21: VTS with IMO mandatory reporting; cargo-based lane allocation; possible mismatch of FINREP limit with amended TSS. | U21: SRC-043; SRC-044; SRC-045; SRC-050 | V21: Salvamento Marítimo website returned HTTP 503/TLS failure, so current VTS name and VHF channel not confirmed from operator; only a 2025 news lead (S22). Check whether FINREP geographical limits were amended after 2004.
A22: TSS-0061 | B22: B13 | C22: A | D22: Off Cape Roca (Cabo da Roca) | E22: Off Cape Roca | F22: Portugal | G22: Confirmed | H22: Amended by MSC 79 (December 2004) with entry into force 1 July 2005 (S23 preamble) and again by COLREG.2/Circ.61 (MSC 87), implemented 1 December 2010 (S26). Established in Portuguese law as 'EST do cabo da Roca' (S23 art. 4). | I22: In force | K22: Confirmed present | L22: VTS-023 | M22: DL 263/2009 art. 6 defines the coastal VTS area (west limit 10° 14' W north of 38° 41' N) and art. 10(4) gives the CCTMC supervision of 'regras aplicáveis aos esquemas de separação de tráfego' (S24); DL 198/2006 art. 9 assigns TSS enforcement to the national VTS authority (S23). All Circ.61 positions of the scheme (westmost 010° 13.78' W) fall inside the statutory VTS area on coordinate comparison (S26). | N22: Confirmed present | O22: SRS-011 | P22: COPREP (MSC.278(85), in force 1 June 2009) area bounded west by 010° 14' W and to the south-west by the line 38° 41' N 010° 14' W to 36° 30' N 009° 35' W (S25); the scheme lies inside on coordinate comparison. Reports to Roca Control. | Q22: COPREP invites any other vessel type to participate voluntarily (S25). | R22: COPREP and VTS: ships of 300 GT or above, dangerous/polluting cargo, passenger ships, tows over 100 m, fishing vessels 24 m or more (S24, S25). Separate lanes for ships carrying dangerous or pollutant cargoes in bulk (S26). | S22: Intermediate | T22: Single national coastal VTS with IMO mandatory reporting and cargo-based lanes. | U22: SRC-046; SRC-047; SRC-048; SRC-049 | V22: DL 263/2009 cites IPTM; current operating authority (DGRM) not confirmed from a DGRM page. Coverage relies on coordinate comparison.
A23: TSS-0062 | B23: B13 | C23: A | D23: Off Cape St. Vicente (Cabo de São Vicente) | E23: Off Cape S. Vicente | F23: Portugal | G23: Confirmed | H23: Amended by MSC 79 (in force 1 July 2005) (S23 preamble) and COLREG.2/Circ.61, implemented 1 December 2010 (S26). 'EST do cabo de São Vicente' in Portuguese law (S23 art. 4). | I23: In force | K23: Confirmed present | L23: VTS-023 | M23: As TSS-0061: statutory VTS area and CCTMC duty to supervise TSS rules (S24 art. 6, 10(4)); DL 198/2006 art. 9 (S23). Circ.61 positions (around 36° 36' to 37° 02' N, 008° 58' to 009° 34' W for retrieved points) lie inside the VTS area line 38° 41' N 10° 14' W to 36° 30' N 9° 35' W on coordinate comparison (S26). | N23: Confirmed present | O23: SRS-011 | P23: COPREP area (S25) encloses the scheme on coordinate comparison; reports to Roca Control. | Q23: COPREP voluntary participation for other vessel types (S25). | R23: As TSS-0061. | S23: Intermediate | T23: As TSS-0061. | U23: SRC-046; SRC-047; SRC-048; SRC-049 | V23: Outermost southbound dangerous-cargo lane coordinates not all extracted; verify it lies east of the COPREP/VTS boundary.
A24: TSS-0063 | B24: B13 | C24: A | D24: At Banco del Hoyo | E24: At Banco del Hoyo | F24: Spain (presumed) | G24: Provisional | H24: Listed in IMO Ships' Routeing 2008 contents, Section II Western European waters, page II/32, after Off Cape S. Vicente (S27), and in Transportstyrelsen 2017 list as adopted by A.284(VIII) 1973 with no later amendment (S4). Location, coordinates and responsible State not retrieved. | I24: In force | K24: Unresolved | M24: Location not established, so no VTS coverage could be tested. Possible leads (not evidenced): Tarifa VTS / GIBREP if the scheme lies in the western approach to the Strait of Gibraltar, but GIBREP area is 005° 58' W to 005° 15' W only (MSC.63(67) annex 2, S20). | N24: Unresolved | P24: No reporting system linked; location not established. | S24: Not assessed | T24: Identity and location unresolved. | U24: SRC-027; SRC-043; SRC-050; SRC-053 | V24: Retrieve Ships' Routeing Part B II/32 or resolution A.284(VIII) to fix location; confirm whether still in force in 2026.
